#VRML_SIM R2022a utf8
WorldInfo {
}
Viewpoint {
  orientation -0.33185733874619844 -0.09874274160469809 0.9381474178937331 3.686018050088086
  position 1.700313773507203 1.0549607538959629 1.4846240848267684
  follow "camera_1"
}
TexturedBackground {
}
TexturedBackgroundLight {
}
CircleArena {
}
Robot {
  translation 0 0 0
  rotation 0 0 1 -2.356194487
  children [
    HingeJoint {
      endPoint Solid {
        translation 0.045 0 0
        rotation 0 1 0 1.5708
        children [
          Shape {
            appearance PBRAppearance {
            }
            geometry Cylinder {
              height 0.015
              radius 0.01
            }
          }
          Camera {
            translation 0 0 0.0075
            rotation 0 -1 0 1.570796325
            width 720
            height 480
            name "cam_1"
          }
        ]
      }
    }
    Transform {
      translation 0 0 0
      children [
        Shape {
          appearance PBRAppearance {
            roughness 0.5
          }
          geometry DEF BODY Box {
                size 0.075 0.05 0.03
              }
        }
      ]
    } 
  ]
  boundingObject Transform {
    translation 0 0 0
    children [
      USE BODY
    ]
  }
  controller "<extern>"
  name "camera_1"
}

